{"additions": 4361, "auther_ref": "fix_py27exceptions", "auther_sha": "f2773c1e36ca89e582a02eb21b5daa905091d733", "author": "ericvaandering", "body": "Combination of what was requested in #12019 and #11964 .\n\nThe preferred form of both how one raises exceptions and catches them with `except` has changed in python 2.6 and python 3 will not take the old forms.\n\nThese changes were all done with futurize, an automated tool.\n\nSee See https://www.python.org/dev/peps/pep-3109/ and  https://www.python.org/dev/peps/pep-3110/#compatibility for details\n", "branch": "CMSSW_8_0_X", "changed_files": 245, "closed_at": "1446199865", "comments": 18, "commits": 1, "created_at": "1445494981", "deletions": 4381, "labels": ["alca-pending", "analysis-pending", "comparison-available", "core-approved", "daq-approved", "db-pending", "docs-pending", "dqm-pending", "geometry-approved", "hlt-approved", "operations-pending", "orp-pending", "pdmv-pending", "pending-signatures", "reconstruction-rejected", "simulation-approved", "tests-approved"], "milestone": "CMSSW_8_0_X", "number": 12039, "release-notes": [], "review_comments": 0, "state": "closed", "title": "Modernize exception raising and catching", "updated_at": "1446199865", "user": "ericvaandering"}